Workbook

Sheet Accounts
A1: SIGMA OMEGA NU
A2: LATINA INTEREST SORORITY
A3: FINANCIAL BOOK
A4: General Ledger Accounts
A5: Account Description | B5: Account # | D5: Account Description | E5: Account #
A7: Revenue | D7: Expenses
A8: Membership Dues | B8: 100 | D8: National Board Dues | E8: 200
A9: Pledge Class Dues | B9: 101 | D9: Pledge Class Costs | E9: 201
A10: Fines | B10: 102 | D10: Recruitment Expenses | E10: 202
A11: Paraphernalia Fundraiser Sales | B11: 107 | D11: Council Dues | E11: 203
A12: Food/Club/Party Fundraiser Sales | B12: 108 | D12: Socials/Retreats | E12: 204
A13: Raffles/Auctions Fundraiser Sales | B13: 109 | D13: Banking Fees | E13: 205
A14: Other Fundraiser Sales | B14: 110 | D14: Officer Expenses (i.e. Zoom) | E14: 206
A15: Sunnie Summit | B15: 111 | D15: Paraphernalia Fundraiser Expenses | E15: 207
A16: Parent's Banquet | B16: 112 | D16: Food/Club/Party Fundraiser Sales | E16: 208
A17: Official Sweaters | B17: 113 | D17: Raffles/Auctions Fundraiser Expenses | E17: 209
A18: Graduation Stoles | B18: 114 | D18: Other Fundraiser Expenses | E18: 210
A19: National Conference | B19: 115 | D19: Sunnie Summit | E19: 211
... A24: Philanthropy & Community Service | B24: 121 | D24: Battle of the Chapters | E24: 216
D25: Executive Retreat | E25: 217
D26: Formal Payments | E26: 218
D27: Scholarships | E27: 220
D28: Philanthropy & Community Service | E28: 221
A29: Updated by NVP of Finance

Sheet Checkbook
A1: SIGMA OMEGA NU
A2: LATINA INTEREST SORORITY
A3: FINANCIAL BOOK
A4: CHAPTER
A5: 2024 Checkbook
F6: =SUM(F9:F519) -> 2709.04 | G6: =SUM(G9:G519) -> 2851.07
A7: Date | B7: Payment Method | C7: With/Dep | D7: Description of Transaction | E7: Code | F7: Debit (-) | G7: Credit (+) | H7: Balance
D9: Starting Balance
H10: =H9 + IF(G10<>"", G10, 0) - IF(F10<>"", F10, 0) -> 1101.01
H11: =H10 + IF(G11<>"", G11, 0) - IF(F11<>"", F11, 0) -> 1055.26
H12: =H11 + IF(G12<>"", G12, 0) - IF(F12<>"", F12, 0) -> 1023.26
H13: =H12 + IF(G13<>"", G13, 0) - IF(F13<>"", F13, 0) -> 763.26
H14: =H13 + IF(G14<>"", G14, 0) - IF(F14<>"", F14, 0) -> 873.26
H15: =H14 + IF(G15<>"", G15, 0) - IF(F15<>"", F15, 0) -> 1073.26
H16: =H15 + IF(G16<>"", G16, 0) - IF(F16<>"", F16, 0) -> 1273.26
H17: =H16 + IF(G17<>"", G17, 0) - IF(F17<>"", F17, 0) -> 1473.26
H18: =H17 + IF(G18<>"", G18, 0) - IF(F18<>"", F18, 0) -> 1623.26
H19: =H18 + IF(G19<>"", G19, 0) - IF(F19<>"", F19, 0) -> 1773.26
H20: =H19 + IF(G20<>"", G20, 0) - IF(F20<>"", F20, 0) -> 1923.26
H21: =H20 + IF(G21<>"", G21, 0) - IF(F21<>"", F21, 0) -> 1803.26
... H62: =H61 + IF(G62<>"", G62, 0) - IF(F62<>"", F62, 0) -> 1043.04
H63: =sum(H62,G63-F63) -> 1043.04
H64: =sum(H63,G64-F64) -> 1043.04
H65: =sum(H64,G65-F65) -> 1043.04
H66: =sum(H65,G66-F66) -> 1043.04
H67: =sum(H66,G67-F67) -> 1043.04
H68: =sum(H67,G68-F68) -> 1043.04
H69: =sum(H68,G69-F69) -> 1043.04
H70: =sum(H69,G70-F70) -> 1043.04
H71: =sum(H70,G71-F71) -> 1043.04
H72: =sum(H71,G72-F72) -> 1043.04
H73: =sum(H72,G73-F73) -> 1043.04
H74: =sum(H73,G74-F74) -> 1043.04
... H286: =sum(H285,G286-F286) -> 1043.04
E287: - | H287: =sum(H286,G287-F287) -> 1043.04
E288: - | H288: =sum(H287,G288-F288) -> 1043.04
E289: - | H289: =sum(H288,G289-F289) -> 1043.04
E290: - | H290: =sum(H289,G290-F290) -> 1043.04
E291: - | H291: =sum(H290,G291-F291) -> 1043.04
E292: - | H292: =sum(H291,G292-F292) -> 1043.04
...

Sheet Summary
A1: Re
A2: LATINA INTEREST SORORITY
A3: FINANCIAL BOOK
A4: CHAPTER
A5: 2025 Financial Activity Summary
C7: Revenue | E7: Expenses | G7: Total
A8: Membership Dues | B8: 100 | C8: =VLOOKUP(B8,IncStmt!$B$10:$D$24,3,FALSE) -> 1982 | D8: 200 | E8: =VLOOKUP(D8,IncStmt!$B$30:$D$48,3,FALSE) -> 652.5 | F8: = | G8: =C8-E8 -> 1329.5
A9: Pledge Class | B9: 101 | C9: =VLOOKUP(B9,IncStmt!$B$10:$D$24,3,FALSE) -> 450 | D9: 201 | E9: =VLOOKUP(D9,IncStmt!$B$30:$D$48,3,FALSE) -> 215.61 | F9: = | G9: =C9-E9 -> 234.39
A10: Fines | B10: 102 | C10: =VLOOKUP(B10,IncStmt!$B$10:$D$24,3,FALSE) -> 0 | E10: 0 | F10: = | G10: =C10-E10 -> 0
A11: Recruitment Expenses | C11: 0 | D11: 202 | E11: =VLOOKUP(D11,IncStmt!$B$30:$D$48,3,FALSE) -> 43.75 | F11: = | G11: =C11-E11 -> -43.75
A12: Council Dues | D12: 203 | E12: =VLOOKUP(D12,IncStmt!$B$30:$D$48,3,FALSE) -> 270 | F12: = | G12: =C12-E12 -> -270
A13: Socials/Retreats | D13: 204 | E13: =VLOOKUP(D13,IncStmt!$B$30:$D$48,3,FALSE) -> 116.7 | F13: = | G13: =C13-E13 -> -116.7
A14: Banking Fees | D14: 205 | E14: =VLOOKUP(D14,IncStmt!$B$30:$D$48,3,FALSE) -> 0 | F14: = | G14: =C14-E14 -> 0
A15: Officer Expenses (i.e. Zoom) | D15: 206 | E15: =VLOOKUP(D15,IncStmt!$B$30:$D$48,3,FALSE) -> 0 | F15: = | G15: =C15-E15 -> 0
A16: Paraphernalia Fundraiser | B16: 107 | C16: =VLOOKUP(B16,IncStmt!$B$10:$D$24,3,FALSE) -> 0 | D16: 207 | E16: =VLOOKUP(D16,IncStmt!$B$30:$D$48,3,FALSE) -> 0 | F16: = | G16: =C16-E16 -> 0
A17: Food/Club/Party Fundraiser | B17: 108 | C17: =VLOOKUP(B17,IncStmt!$B$10:$D$24,3,FALSE) -> 125 | D17: 208 | E17: =VLOOKUP(D17,IncStmt!$B$30:$D$48,3,FALSE) -> 48.57 | F17: = | G17: =C17-E17 -> 76.43
A18: Raffles/Auctions Fundraiser | B18: 109 | C18: =VLOOKUP(B18,IncStmt!$B$10:$D$24,3,FALSE) -> 0 | D18: 209 | E18: =VLOOKUP(D18,IncStmt!$B$30:$D$48,3,FALSE) -> 0 | F18: = | G18: =C18-E18 -> 0
A19: Other Fundraiser Sales | B19: 110 | C19: =VLOOKUP(B19,IncStmt!$B$10:$D$24,3,FALSE) -> 0 | D19: 210 | E19: =VLOOKUP(D19,IncStmt!$B$30:$D$48,3,FALSE) -> 20.64 | F19: = | G19: =C19-E19 -> -20.64
A20: Sunnie Summit | B20: 111 | C20: =VLOOKUP(B20,IncStmt!$B$10:$D$24,3,FALSE) -> 0 | D20: 211 | E20: =VLOOKUP(D20,IncStmt!$B$30:$D$48,3,FALSE) -> 0 | F20: = | G20: =C20-E20 -> 0
A21: Parent's Banquet | B21: 112 | C21: =VLOOKUP(B21,IncStmt!$B$10:$D$24,3,FALSE) -> 0 | D21: 212 | E21: =VLOOKUP(D21,IncStmt!$B$30:$D$48,3,FALSE) -> 85.86 | F21: = | G21: =C21-E21 -> -85.86
A22: Official Sweaters | B22: 113 | C22: =VLOOKUP(B22,IncStmt!$B$10:$D$24,3,FALSE) -> 0 | D22: 213 | E22: =VLOOKUP(D22,IncStmt!$B$30:$D$48,3,FALSE) -> 0 | F22: = | G22: =C22-E22 -> 0
A23: Graduation Stoles | B23: 114 | C23: =VLOOKUP(B23,IncStmt!$B$10:$D$24,3,FALSE) -> 0 | D23: 214 | E23: =VLOOKUP(D23,IncStmt!$B$30:$D$48,3,FALSE) -> 0 | G23: =C23-E23 -> 0
A24: National Conference | B24: 115 | C24: =VLOOKUP(B24,IncStmt!$B$10:$D$24,3,FALSE) -> 0 | D24: 215 | E24: =VLOOKUP(D24,IncStmt!$B$30:$D$48,3,FALSE) -> 260 | G24: =C24-E24 -> -260
A25: Battle of the Chapters | B25: 116 | C25: =VLOOKUP(B25,IncStmt!$B$10:$D$24,3,FALSE) -> 0 | D25: 216 | E25: =VLOOKUP(D25,IncStmt!$B$30:$D$48,3,FALSE) -> 633.41 | G25: =C25-E25 -> -633.41
A26: Executive Retreat | B26: 117 | C26: =VLOOKUP(B26,IncStmt!$B$10:$D$24,3,FALSE) -> 0 | D26: 217 | E26: =VLOOKUP(D26,IncStmt!$B$30:$D$48,3,FALSE) -> 240 | G26: =C26-E26 -> -240
A27: Formal | B27: 118 | C27: =VLOOKUP(B27,IncStmt!$B$10:$D$24,3,FALSE) -> 0 | D27: 218 | E27: =VLOOKUP(D27,IncStmt!$B$30:$D$48,3,FALSE) -> 45 | F27: = | G27: =C27-E27 -> -45
A28: Donations | B28: 119 | C28: =VLOOKUP(B28,IncStmt!$B$10:$D$26,3,FALSE) -> 64 | E28: 0 | F28: = | G28: =C28-E28 -> 64
A29: Scholarships | D29: 220 | E29: =VLOOKUP(D29,IncStmt!$B$30:$D$51,3,FALSE) -> 0 | F29: = | G29: =C29-E29 -> 0
A30: Philanthropy & Community Service | B30: 121 | D30: 221 | E30: =VLOOKUP(D30,IncStmt!$B$30:$D$51,3,FALSE) -> 77 | F30: = | G30: =C30-E30 -> -77
A31: Total | G31: =SUM(G8:G30) -> -88.04

Sheet IncStmt
A1: SIGMA OMEGA NU
A2: LATINA INTEREST SORORITY
A3: FINANCIAL BOOK
A4: CHAPTER
A5: Income Statement for 2025
A7: Beginning Balance | E7: =Checkbook!H9 -> 901.01
A9: Revenue
B10: 100 | C10: Membership Dues | D10: =SUMIF(Checkbook!$E$9:$E$519,B10,Checkbook!$G$9:$G$407) -> 1982
B11: 101 | C11: Pledge Class Dues | D11: =SUMIF(Checkbook!$E$9:$E$519,B11,Checkbook!$G$9:$G$407) -> 450
B12: 102 | C12: Fines | D12: =SUMIF(Checkbook!$E$9:$E$519,B12,Checkbook!$G$9:$G$407) -> 0
B13: 107 | C13: Paraphernalia Fundraiser Sales | D13: =SUMIF(Checkbook!$E$9:$E$519,B13,Checkbook!$G$9:$G$407) -> 0
B14: 108 | C14: Food/Club/Party Fundraiser Sales | D14: =SUMIF(Checkbook!$E$9:$E$519,B14,Checkbook!$G$9:$G$407) -> 125
B15: 109 | C15: Raffles/Auctions Fundraiser Sales | D15: =SUMIF(Checkbook!$E$9:$E$519,B15,Checkbook!$G$9:$G$407) -> 0
B16: 110 | C16: Other Fundraiser Sales | D16: =SUMIF(Checkbook!$E$9:$E$519,B16,Checkbook!$G$9:$G$407) -> 0
B17: 112 | C17: Parent's Banquet | D17: =SUMIF(Checkbook!$E$9:$E$519,B17,Checkbook!$G$9:$G$407) -> 0
B18: 111 | C18: Sunnie Summit | D18: =SUMIF(Checkbook!$E$9:$E$519,B18,Checkbook!$G$9:$G$407) -> 0
B19: 113 | C19: Official Sweaters | D19: =SUMIF(Checkbook!$E$9:$E$519,B19,Checkbook!$G$9:$G$407) -> 0
B20: 114 | C20: Graduation Stoles | D20: =SUMIF(Checkbook!$E$9:$E$519,B20,Checkbook!$G$9:$G$407) -> 0
B21: 115 | C21: National Conference | D21: =SUMIF(Checkbook!$E$9:$E$519,B21,Checkbook!$G$9:$G$407) -> 0
... B26: 121 | C26: Philanthropy & Community Service | D26: =SUMIF(Checkbook!$E$9:$E$519,B26,Checkbook!$G$9:$G$407) -> 0
E27: =SUM(D9:D26) -> 2621
A29: Expenses
B30: 200 | C30: National Board Dues | D30: =SUMIF(Checkbook!$E$9:$E$519,B30,Checkbook!$F$9:$F$519) -> 652.5
B31: 201 | C31: Pledge Class Costs | D31: =SUMIF(Checkbook!$E$9:$E$519,B31,Checkbook!$F$9:$F$519) -> 215.61
B32: 202 | C32: Recruitment Expenses | D32: =SUMIF(Checkbook!$E$9:$E$519,B32,Checkbook!$F$9:$F$519) -> 43.75
B33: 203 | C33: Council Dues | D33: =SUMIF(Checkbook!$E$9:$E$519,B33,Checkbook!$F$9:$F$519) -> 270
B34: 204 | C34: Socials/Retreats | D34: =SUMIF(Checkbook!$E$9:$E$519,B34,Checkbook!$F$9:$F$519) -> 116.7
B35: 205 | C35: Banking Fees | D35: =SUMIF(Checkbook!$E$9:$E$519,B35,Checkbook!$F$9:$F$519) -> 0
B36: 206 | C36: Officer Expenses (i.e. Zoom) | D36: =SUMIF(Checkbook!$E$9:$E$519,B36,Checkbook!$F$9:$F$519) -> 0
B37: 207 | C37: Paraphernalia Fundraiser Sales | D37: =SUMIF(Checkbook!$E$9:$E$519,B37,Checkbook!$F$9:$F$519) -> 0
B38: 208 | C38: Food/Club/Party Fundraiser Sales | D38: =SUMIF(Checkbook!$E$9:$E$519,B38,Checkbook!$F$9:$F$519) -> 48.57
B39: 209 | C39: Raffles/Auctions Fundraiser Expenses | D39: =SUMIF(Checkbook!$E$9:$E$519,B39,Checkbook!$F$9:$F$519) -> 0
B40: 210 | C40: Other Fundraiser Expenses | D40: =SUMIF(Checkbook!$E$9:$E$519,B40,Checkbook!$F$9:$F$519) -> 20.64
B41: 211 | C41: Sunnie Summit | D41: =SUMIF(Checkbook!$E$9:$E$519,B41,Checkbook!$F$9:$F$519) -> 0
... B50: 221 | C50: Philanthropy & Community Service | D50: =SUMIF(Checkbook!$E$9:$E$519,B50,Checkbook!$F$9:$F$519) -> 77
E51: =SUM(D27:D50) -> 2709.04
A53: Ending Balance | E53: =E7+E27-E51 -> 812.97

Sheet Budget Log
A1: SIGMA OMEGA NU
A2: LATINA INTEREST SORORITY
A3: FINANCIAL BOOK
A4: 2025 Chapter Budget Log
A5: Budget Number | B5: Tentative/Final | C5: Submitted By | D5: Date Due | E5: Date Submitted | F5: Date Presented | G5: Description | H5: Amount | I5: Check # | J5: Votes | K5: Status | L5: Reimbursement amount & method
