Workbook

Sheet INSTRUCTIONS
A3: START HERE FIRST
K5: Yes
B6: What is the Sales Tax for your area? | K6: No
B7: If you don't have sales tax, enter 0
A9: TENTATIVE BUDGET
A11: 1 | B11: Enter event name, event chair and date of the event. The box that says "Budget #" leave blank. That is for the Treasurer/Auditor to fill in.
A12: 2 | B12: List all expected expenses for the event along with approximate costs. This does require you to go find out how much these items actually cost. If not, you risk not requresting enough money to cover all expenses. Or, you request too much and your budget is not approved because it is too high.
A13: 3 | B13: Turn in to the Auditor by the date requested. If not turned in by the due date for review and approval, you may be required to pay for everything yourself.
A14: 4 | B14: Use your approved tentative budget as a spending guide. If there are expenses you forgot, it's okay because you can put them on the final budget. However, anything no listed on the tentative budget is not required to be reimbursed. So make sure your expenses are actually appropriate.
A17: FINAL BUDGET
A18: 1 | B18: As you are making purchases for your event, you must keep all receipts. Make sure not to include any personal expenses in the same transaction. This will help you keep track of your spending for your final budget later.
A19: 2 | B19: Using your tetnative budget as a guide, begin adding in the information required for the final budget. Make sure to include all expenses not originally included on the tentative budget.
A20: 3 | B20: The the Special Instructions box at the bottom, identify any special situations or circumstances. Identify which sisters need to be reimbursed and how much. Identify how much money from the tentative bedget was unused, if any.
A21: 4 | B21: Turn your budget and all supporting receipts in by the date identified. If not turned in on time, the sorority is not required to reimburse you for any additional expenses. In addition, you will be held liable for the full amount of the tentative budget and required to return the full amount to the sorority. Any unused funds should also be returned to the sorority.

Sheet Tentative Budget
A1: Sigma Omega Nu Tentative Expenditure Report | E1: Budget #:
E3: Event:
E4: Chair:
E5: Date of Event:
A6: \ | D6: Quantity | E6: Price | G6: Total $ Spent
G7: =D7*E7 -> 0
G8: =D8*E8 -> 0
G9: =D9*E9 -> 0
G10: =D10*E10 -> 0
G11: =D11*E11 -> 0
G12: =D12*E12 -> 0
G13: =D13*E13 -> 0
G14: =D14*E14 -> 0
G15: =D15*E15 -> 0
G16: =D16*E16 -> 0
G17: =D17*E17 -> 0
G18: =D18*E18 -> 0
... G43: =D43*E43 -> 0
A44: [Notes or special instructions. Include any special circumstances, etc.]
F45: Subtotal: | G45: =SUM(G7:G43) -> 0
F46: Tax: | G46: 0
F47: Subtotal: | G47: =G46+G45 -> 0
F48: Income:
F49: Total Spent: | G49: =G47-G48 -> 0
A50: NVP Finance / Comptroller Use Only
A51: Motion:
A53: Second: | D53: Date Due: | F53: Check #:
A55: Vote: | D55: Date Rcv'd: | F55: Check Amount:

Sheet Final Budget
A1: Sigma Omega Nu Final Expenditure Report | E1: Budget #:
E3: Event:
E4: Chair:
E5: Date of Event:
A6: Item | D6: Quantity | E6: Price | F6: Taxable? | G6: Tax | H6: Total $ Spent
G7: =IF(F7="Yes",E7*D7*INSTRUCTIONS!G6,"") | H7: =D7*E7 -> 0
G8: =IF(F8="Yes",E8*D8*INSTRUCTIONS!G6,"") | H8: =D8*E8 -> 0
G9: =IF(F9="Yes",E9*D9*INSTRUCTIONS!G6,"") | H9: =D9*E9 -> 0
G10: =IF(F10="Yes",E10*D10*INSTRUCTIONS!G6,"") | H10: =D10*E10 -> 0
G11: =IF(F11="Yes",E11*D11*INSTRUCTIONS!G6,"") | H11: =D11*E11 -> 0
G12: =IF(F12="Yes",E12*D12*INSTRUCTIONS!G6,"") | H12: =D12*E12 -> 0
G13: =IF(F13="Yes",E13*D13*INSTRUCTIONS!G6,"") | H13: =D13*E13 -> 0
G14: =IF(F14="Yes",E14*D14*INSTRUCTIONS!G6,"") | H14: =D14*E14 -> 0
G15: =IF(F15="Yes",E15*D15*INSTRUCTIONS!G6,"") | H15: =D15*E15 -> 0
G16: =IF(F16="Yes",E16*D16*INSTRUCTIONS!G6,"") | H16: =D16*E16 -> 0
G17: =IF(F17="Yes",E17*D17*INSTRUCTIONS!G6,"") | H17: =D17*E17 -> 0
G18: =IF(F18="Yes",E18*D18*INSTRUCTIONS!G6,"") | H18: =D18*E18 -> 0
G19: =IF(F19="Yes",E19*D19*INSTRUCTIONS!G6,"") | H19: =D19*E19 -> 0
G20: =IF(F20="Yes",E20*D20*INSTRUCTIONS!G6,"") | H20: =D20*E20 -> 0
G21: =IF(F21="Yes",E21*D21*INSTRUCTIONS!G6,"") | H21: =D21*E21 -> 0
G22: =IF(F22="Yes",E22*D22*INSTRUCTIONS!G6,"") | H22: =D22*E22 -> 0
G23: =IF(F23="Yes",E23*D23*INSTRUCTIONS!G6,"") | H23: =D23*E23 -> 0
G24: =IF(F24="Yes",E24*D24*INSTRUCTIONS!G6,"") | H24: =D24*E24 -> 0
G25: =IF(F25="Yes",E25*D25*INSTRUCTIONS!G6,"") | H25: =D25*E25 -> 0
G26: =IF(F26="Yes",E26*D26*INSTRUCTIONS!G6,"") | H26: =D26*E26 -> 0
G27: =IF(F27="Yes",E27*D27*INSTRUCTIONS!G6,"") | H27: =D27*E27 -> 0
G28: =IF(F28="Yes",E28*D28*INSTRUCTIONS!G6,"") | H28: =D28*E28 -> 0
G29: =IF(F29="Yes",E29*D29*INSTRUCTIONS!G6,"") | H29: =D29*E29 -> 0
G30: =IF(F30="Yes",E30*D30*INSTRUCTIONS!G6,"") | H30: =D30*E30 -> 0
G31: =IF(F31="Yes",E31*D31*INSTRUCTIONS!G6,"") | H31: =D31*E31 -> 0
G32: =IF(F32="Yes",E32*D32*INSTRUCTIONS!G6,"") | H32: =D32*E32 -> 0
G33: =IF(F33="Yes",E33*D33*INSTRUCTIONS!G6,"") | H33: =D33*E33 -> 0
G34: =IF(F34="Yes",E34*D34*INSTRUCTIONS!G6,"") | H34: =D34*E34 -> 0
G35: =IF(F35="Yes",E35*D35*INSTRUCTIONS!G6,"") | H35: =D35*E35 -> 0
G36: =IF(F36="Yes",E36*D36*INSTRUCTIONS!G6,"") | H36: =D36*E36 -> 0
G37: =IF(F37="Yes",E37*D37*INSTRUCTIONS!G6,"") | H37: =D37*E37 -> 0
G38: =IF(F38="Yes",E38*D38*INSTRUCTIONS!G6,"") | H38: =D38*E38 -> 0
G39: =IF(F39="Yes",E39*D39*INSTRUCTIONS!G6,"") | H39: =D39*E39 -> 0
G40: =IF(F40="Yes",E40*D40*INSTRUCTIONS!G6,"") | H40: =D40*E40 -> 0
G41: =IF(F41="Yes",E41*D41*INSTRUCTIONS!G6,"") | H41: =D41*E41 -> 0
...
